Workbook

Sheet Rep1
A1: Coulter Counter Counts: MCF7f +10pM E2/500nM ICI/250nM Palbo/-E2 +100nM Palbo 3 weeks (10%CCS+10nM E2)
A2: Thurs 6/13/2019, 45k cells plated on (13) 60mm dishes of MCF7f p82+17+30.
A3: Friday 6/14/19, Count T=0 plate. Wash all remaining plates 1x with PBS, dose accordingly: (3) +10pM E2 (3) -E2+100nM Palbo (3) +E2+250nM Palbo (3) +E2+500nM ICI *Re-dosed plates every Monday and Friday, counted each week on Friday
A5: Day 0 (6/14)
A6: +E2
A7: Sample | B7: Counter Read | C7: Cells/mL | D7: mL of cells | E7: Total cell number | F7: Average total cell # | G7: Stdev
A8: +E2 #1 | B8: 38 | C8: =B8*400 -> 15200 | D8: 2.5 | E8: =C8*D8 -> 38000 | F8: =AVERAGE(E8:E10) -> 39000 | G8: =_xlfn.STDEV.S(E8:E10) -> 3605.5513
A9: +E2 #2 | B9: 36 | C9: =B9*400 -> 14400 | D9: 2.5 | E9: =C9*D9 -> 36000
A10: +E2 #3 | B10: 43 | C10: =B10*400 -> 17200 | D10: 2.5 | E10: =C10*D10 -> 43000
A12: Week 1 (6/21)
A13: +10pM E2 | I13: +E2 +500nM ICI
A14: Sample | B14: Counter Read | C14: Cells/mL | D14: mL of cells | E14: Total cell number | F14: Average total cell # | G14: Stdev | I14: Sample | J14: Counter Read | K14: Cells/mL | L14: mL of cells | M14: Total cell number | N14: Average total cell # | O14: Stdev
A15: +10pM E2 #1 | B15: 952 | C15: =B15*400 -> 380800 | D15: 2.5 | E15: =C15*D15 -> 952000 | F15: =AVERAGE(E15:E17) -> 943000 | G15: =_xlfn.STDEV.S(E15:E17) -> 16462.078 | I15: +E2 +500nM ICI #1 | J15: 132 | K15: =J15*400 -> 52800 | L15: 2.5 | M15: =K15*L15 -> 132000 | N15: =AVERAGE(M15:M17) -> 140000 | O15: =_xlfn.STDEV.S(K15:K17) -> 3019.9338
A16: +10pM E2 #2 | B16: 924 | C16: =B16*400 -> 369600 | D16: 2.5 | E16: =C16*D16 -> 924000 | I16: +E2 +500nM ICI #2 | J16: 141 | K16: =J16*400 -> 56400 | L16: 2.5 | M16: =K16*L16 -> 141000
A17: +10pM E2 #3 | B17: 953 | C17: =B17*400 -> 381200 | D17: 2.5 | E17: =C17*D17 -> 953000 | I17: +E2 +500nM ICI #3 | J17: 147 | K17: =J17*400 -> 58800 | L17: 2.5 | M17: =K17*L17 -> 147000
A19: +E2 +250nM Palbo | I19: -E2 +100nM Palbo
A20: Sample | B20: Counter Read | C20: Cells/mL | D20: mL of cells | E20: Total cell number | F20: Average total cell # | G20: Stdev | I20: Sample | J20: Counter Read | K20: Cells/mL | L20: mL of cells | M20: Total cell number | N20: Average total cell # | O20: Stdev
A21: +E2+250nM Palbo #1 | B21: 205 | C21: =B21*400 -> 82000 | D21: 2.5 | E21: =C21*D21 -> 205000 | F21: =AVERAGE(E21:E23) -> 189666.67 | G21: =_xlfn.STDEV.S(E21:E23) -> 14189.198 | I21: -E2+100nM Palbo #1 | J21: 103 | K21: =J21*400 -> 41200 | L21: 2.5 | M21: =K21*L21 -> 103000 | N21: =AVERAGE(M21:M23) -> 114333.33 | O21: =_xlfn.STDEV.S(M21:M23) -> 11503.623
A22: +E2+250nM Palbo #2 | B22: 187 | C22: =B22*400 -> 74800 | D22: 2.5 | E22: =C22*D22 -> 187000 | I22: -E2+100nM Palbo #2 | J22: 114 | K22: =J22*400 -> 45600 | L22: 2.5 | M22: =K22*L22 -> 114000
A23: +E2+250nM Palbo #3 | B23: 177 | C23: =B23*400 -> 70800 | D23: 2.5 | E23: =C23*D23 -> 177000 | I23: -E2+100nM Palbo #3 | J23: 126 | K23: =J23*400 -> 50400 | L23: 2.5 | M23: =K23*L23 -> 126000
A27: Week 2 (6/28)
A28: +10pM E2 *Very Confluent | I28: +E2 +500nM ICI
A29: Sample | B29: Counter Read | C29: Cells/mL | D29: mL of cells | E29: Total cell number | F29: Average total cell # | G29: Stdev | I29: Sample | J29: Counter Read | K29: Cells/mL | L29: mL of cells | M29: Total cell number | N29: Average total cell # | O29: Stdev
A30: +10pM E2 #1 | B30: 3694 | C30: =B30*400 -> 1477600 | D30: 2.5 | E30: =C30*D30 -> 3694000 | F30: =AVERAGE(E30:E32) -> 3640333.3 | G30: =_xlfn.STDEV.S(E30:E32) -> 49318.692 | I30: +E2 +500nM ICI #1 | J30: 221 | K30: =J30*400 -> 88400 | L30: 2.5 | M30: =K30*L30 -> 221000 | N30: =AVERAGE(M30:M32) -> 205333.33 | O30: =_xlfn.STDEV.S(K30:K32) -> 5604.7599
A31: +10pM E2 #2 | B31: 3630 | C31: =B31*400 -> 1452000 | D31: 2.5 | E31: =C31*D31 -> 3630000 | I31: +E2 +500nM ICI #2 | J31: 201 | K31: =J31*400 -> 80400 | L31: 2.5 | M31: =K31*L31 -> 201000
A32: +10pM E2 #3 | B32: 3597 | C32: =B32*400 -> 1438800 | D32: 2.5 | E32: =C32*D32 -> 3597000 | I32: +E2 +500nM ICI #3 | J32: 194 | K32: =J32*400 -> 77600 | L32: 2.5 | M32: =K32*L32 -> 194000
A34: +E2 +250nM Palbo *Getting confluent | I34: -E2 +100nM Palbo
A35: Sample | B35: Counter Read | C35: Cells/mL | D35: mL of cells | E35: Total cell number | F35: Average total cell # | G35: Stdev | I35: Sample | J35: Counter Read | K35: Cells/mL | L35: mL of cells | M35: Total cell number | N35: Average total cell # | O35: Stdev
A36: +E2+250nM Palbo #1 | B36: 1506 | C36: =B36*400 -> 602400 | D36: 2.5 | E36: =C36*D36 -> 1506000 | F36: =AVERAGE(E36:E38) -> 1463333.3 | G36: =_xlfn.STDEV.S(E36:E38) -> 50212.88 | I36: -E2+100nM Palbo #1 | J36: 89 | K36: =J36*400 -> 35600 | L36: 2.5 | M36: =K36*L36 -> 89000 | N36: =AVERAGE(M36:M38) -> 97333.333 | O36: =_xlfn.STDEV.S(M36:M38) -> 9073.7717
A37: +E2+250nM Palbo #2 | B37: 1408 | C37: =B37*400 -> 563200 | D37: 2.5 | E37: =C37*D37 -> 1408000 | I37: -E2+100nM Palbo #2 | J37: 107 | K37: =J37*400 -> 42800 | L37: 2.5 | M37: =K37*L37 -> 107000
A38: +E2+250nM Palbo #3 | B38: 1476 | C38: =B38*400 -> 590400 | D38: 2.5 | E38: =C38*D38 -> 1476000 | I38: -E2+100nM Palbo #3 | J38: 96 | K38: =J38*400 -> 38400 | L38: 2.5 | M38: =K38*L38 -> 96000
A42: Week 3 (7/6)
A43: +10pM E2 | I43: +E2 +500nM ICI
A44: Sample | B44: Counter Read | C44: Cells/mL | D44: mL of cells | E44: Total cell number | F44: Average total cell # | G44: Stdev | I44: Sample | J44: Counter Read | K44: Cells/mL | L44: mL of cells | M44: Total cell number | N44: Average total cell # | O44: Stdev
A45: +10pM E2 #1 | B45: 4340 | C45: =B45*400 -> 1736000 | D45: 2.5 | E45: =C45*D45 -> 4340000 | F45: =AVERAGE(E45:E47) -> 4290333.3 | G45: =_xlfn.STDEV.S(E45:E47) -> 227601.26 | I45: +E2 +500nM ICI #1 | J45: 503 | K45: =J45*400 -> 201200 | L45: 2.5 | M45: =K45*L45 -> 503000 | N45: =AVERAGE(M45:M47) -> 537000 | O45: =_xlfn.STDEV.S(K45:K47) -> 12106.197
A46: +10pM E2 #2 | B46: 4042 | C46: =B46*400 -> 1616800 | D46: 2.5 | E46: =C46*D46 -> 4042000 | I46: +E2 +500nM ICI #2 | J46: 561 | K46: =J46*400 -> 224400 | L46: 2.5 | M46: =K46*L46 -> 561000
A47: +10pM E2 #3 | B47: 4489 | C47: =B47*400 -> 1795600 | D47: 2.5 | E47: =C47*D47 -> 4489000 | I47: +E2 +500nM ICI #3 | J47: 547 | K47: =J47*400 -> 218800 | L47: 2.5 | M47: =K47*L47 -> 547000
A49: +E2 +250nM Palbo | I49: -E2 +100nM Palbo
A50: Sample | B50: Counter Read | C50: Cells/mL | D50: mL of cells | E50: Total cell number | F50: Average total cell # | G50: Stdev | I50: Sample | J50: Counter Read | K50: Cells/mL | L50: mL of cells | M50: Total cell number | N50: Average total cell # | O50: Stdev
A51: +E2+250nM Palbo #1 | B51: 2380 | C51: =B51*400 -> 952000 | D51: 2.5 | E51: =C51*D51 -> 2380000 | F51: =AVERAGE(E51:E53) -> 2416333.3 | G51: =_xlfn.STDEV.S(E51:E53) -> 178298.44 | I51: -E2+100nM Palbo #1 | J51: 64 | K51: =J51*400 -> 25600 | L51: 2.5 | M51: =K51*L51 -> 64000 | N51: =AVERAGE(M51:M53) -> 66000 | O51: =_xlfn.STDEV.S(M51:M53) -> 5291.5026
...

Sheet Sheet1
A2: Day 0
A3: +E2
A4: Sample | B4: Counter Read
A5: +E2 #1 | B5: ='Rep1'!B8 -> 38
A6: +E2 #2 | B6: ='Rep1'!B9 -> 36
A7: +E2 #3 | B7: ='Rep1'!B10 -> 43
A9: Week 1 | G9: Week 1
A10: +10pM E2 | D10: +E2 +500nM ICI | G10: +10pM E2 | J10: +E2 +500nM ICI | N10: Day0 | O10: Week1 | P10: Week2 | Q10: Week3
A11: Sample | B11: Counter Read | D11: Sample | E11: Counter Read | G11: Sample | H11: Counter Read | J11: Sample | K11: Counter Read | M11: +10pM E2 | N11: 1 | O11: =AVERAGE(H12:H14) -> 24.29403 | P11: =AVERAGE(H26:H28) -> 93.898341 | Q11: =AVERAGE(H40:H42) -> 110.29455
A12: +10pM E2 #1 | B12: ='Rep1'!B15 -> 952 | D12: +E2 +500nM ICI #1 | E12: ='Rep1'!J15 -> 132 | G12: +10pM E2 #1 | H12: =B12/B5 -> 25.052632 | J12: +E2 +500nM ICI #1 | K12: =E12/B5 -> 3.4736842 | M12: +E2 +500nM ICI | N12: 1 | O12: =AVERAGE(K12:K14) -> 3.6029852 | P12: =AVERAGE(K26:K28) -> 5.3035836 | Q12: =AVERAGE(K40:K42) -> 13.847035
A13: +10pM E2 #2 | B13: ='Rep1'!B16 -> 924 | D13: +E2 +500nM ICI #2 | E13: ='Rep1'!J16 -> 141 | G13: +10pM E2 #2 | H13: =B13/B6 -> 25.666667 | J13: +E2 +500nM ICI #2 | K13: =E13/B6 -> 3.9166667 | M13: +E2 +250nM Palbo | N13: 1 | O13: =AVERAGE(H18:H20) -> 4.9018201 | P13: =AVERAGE(H32:H34) -> 37.689424 | Q13: =AVERAGE(H46:H48) -> 62.555488
A14: +10pM E2 #3 | B14: ='Rep1'!B17 -> 953 | D14: +E2 +500nM ICI #3 | E14: ='Rep1'!J17 -> 147 | G14: +10pM E2 #3 | H14: =B14/B7 -> 22.162791 | J14: +E2 +500nM ICI #3 | K14: =E14/B7 -> 3.4186047 | M14: -E2 + 100nM Palbo | N14: 1 | O14: =AVERAGE(K18:K20) -> 2.9358085 | P14: =AVERAGE(K32:K34) -> 2.5156285 | Q14: =AVERAGE(K46:K48) -> 1.6936171
A16: +E2 +250nM Palbo | D16: -E2 + 100nM Palbo | G16: +E2 +250nM Palbo | J16: -E2 + 100nM Palbo
A17: Sample | B17: Counter Read | D17: Sample | E17: Counter Read | G17: Sample | H17: Counter Read | J17: Sample | K17: Counter Read
A18: +E2+Palbo 250nM #1 | B18: ='Rep1'!B21 -> 205 | D18: -E2 + 100nM Palbo #1 | E18: ='Rep1'!J21 -> 103 | G18: +E2 +250nM Palbo #1 | H18: =B18/B5 -> 5.3947368 | J18: -E2 + 100nM Palbo #1 | K18: =E18/B5 -> 2.7105263
A19: +E2+Palbo 250nM #2 | B19: ='Rep1'!B22 -> 187 | D19: -E2 + 100nM Palbo #2 | E19: ='Rep1'!J22 -> 114 | G19: +E2 +250nM Palbo #2 | H19: =B19/B6 -> 5.1944444 | J19: -E2 + 100nM Palbo #2 | K19: =E19/B6 -> 3.1666667
A20: +E2+Palbo 250nM #3 | B20: ='Rep1'!B23 -> 177 | D20: -E2 + 100nM Palbo #3 | E20: ='Rep1'!J23 -> 126 | G20: +E2 +250nM Palbo #3 | H20: =B20/B7 -> 4.1162791 | J20: -E2 + 100nM Palbo #3 | K20: =E20/B7 -> 2.9302326
A23: Week 2 | G23: Week 2
A24: +10pM E2 | D24: +E2 +500nM ICI | G24: +10pM E2 | J24: +E2 +500nM ICI
A25: Sample | B25: Counter Read | D25: Sample | E25: Counter Read | G25: Sample | H25: Counter Read | J25: Sample | K25: Counter Read
A26: +10pM E2 #1 | B26: ='Rep1'!B30 -> 3694 | D26: +E2 +500nM ICI #1 | E26: ='Rep1'!J30 -> 221 | G26: +10pM E2 #1 | H26: =B26/B5 -> 97.210526 | J26: +E2 +500nM ICI #1 | K26: =E26/B5 -> 5.8157895
A27: +10pM E2 #2 | B27: ='Rep1'!B31 -> 3630 | D27: +E2 +500nM ICI #1 | E27: ='Rep1'!J31 -> 201 | G27: +10pM E2 #2 | H27: =B27/B6 -> 100.83333 | J27: +E2 +500nM ICI #2 | K27: =E27/B6 -> 5.5833333
A28: +10pM E2 #3 | B28: ='Rep1'!B32 -> 3597 | D28: +E2 +500nM ICI #1 | E28: ='Rep1'!J32 -> 194 | G28: +10pM E2 #3 | H28: =B28/B7 -> 83.651163 | J28: +E2 +500nM ICI #3 | K28: =E28/B7 -> 4.5116279
A30: +E2 +250nM Palbo | D30: -E2 + 100nM Palbo | G30: +E2 +250nM Palbo | J30: -E2 + 100nM Palbo
A31: Sample | B31: Counter Read | D31: Sample | E31: Counter Read | G31: Sample | H31: Counter Read | J31: Sample | K31: Counter Read
A32: +E2+Palbo 250nM #1 | B32: ='Rep1'!B36 -> 1506 | D32: -E2 + 100nM Palbo #1 | E32: ='Rep1'!J36 -> 89 | G32: +E2 +250nM Palbo #1 | H32: =B32/B5 -> 39.631579 | J32: -E2 + 100nM Palbo #1 | K32: =E32/B5 -> 2.3421053
A33: +E2+Palbo 250nM #2 | B33: ='Rep1'!B37 -> 1408 | D33: -E2 + 100nM Palbo #2 | E33: ='Rep1'!J37 -> 107 | G33: +E2 +250nM Palbo #2 | H33: =B33/B6 -> 39.111111 | J33: -E2 + 100nM Palbo #2 | K33: =E33/B6 -> 2.9722222
A34: +E2+Palbo 250nM #3 | B34: ='Rep1'!B38 -> 1476 | D34: -E2 + 100nM Palbo #3 | E34: ='Rep1'!J38 -> 96 | G34: +E2 +250nM Palbo #3 | H34: =B34/B7 -> 34.325581 | J34: -E2 + 100nM Palbo #3 | K34: =E34/B7 -> 2.2325581
A37: Week 3 | G37: Week 3
A38: +10pM E2 | D38: +E2 +500nM ICI | G38: +10pM E2 | J38: +E2 +500nM ICI
A39: Sample | B39: Counter Read | D39: Sample | E39: Counter Read | G39: Sample | H39: Counter Read | J39: Sample | K39: Counter Read
A40: +10pM E2 #1 | B40: ='Rep1'!B45 -> 4340 | D40: +E2 +500nM ICI #1 | E40: ='Rep1'!J45 -> 503 | G40: +10pM E2 #1 | H40: =B40/B5 -> 114.21053 | J40: +E2 +500nM ICI #1 | K40: =E40/B5 -> 13.236842
A41: +10pM E2 #2 | B41: ='Rep1'!B46 -> 4042 | D41: +E2 +500nM ICI #2 | E41: ='Rep1'!J46 -> 561 | G41: +10pM E2 #2 | H41: =B41/B6 -> 112.27778 | J41: +E2 +500nM ICI #2 | K41: =E41/B6 -> 15.583333
A42: +10pM E2 #3 | B42: ='Rep1'!B47 -> 4489 | D42: +E2 +500nM ICI #3 | E42: ='Rep1'!J47 -> 547 | G42: +10pM E2 #3 | H42: =B42/B7 -> 104.39535 | J42: +E2 +500nM ICI #3 | K42: =E42/B7 -> 12.72093
A44: +E2 +250nM Palbo | D44: -E2 + 100nM Palbo | G44: +E2 +250nM Palbo | J44: -E2 + 100nM Palbo
A45: Sample | B45: Counter Read | D45: Sample | E45: Counter Read | G45: Sample | H45: Counter Read | J45: Sample | K45: Counter Read
A46: +E2 +250nM Palbo #1 | B46: ='Rep1'!B51 -> 2380 | D46: -E2 + 100nM Palbo #1 | E46: ='Rep1'!J51 -> 64 | G46: +E2 +250nM Palbo #1 | H46: =B46/B5 -> 62.631579 | J46: -E2 + 100nM Palbo #1 | K46: =E46/B5 -> 1.6842105
A47: +E2 +250nM Palbo #2 | B47: ='Rep1'!B52 -> 2610 | D47: -E2 + 100nM Palbo #2 | E47: ='Rep1'!J52 -> 62 | G47: +E2 +250nM Palbo #2 | H47: =B47/B6 -> 72.5 | J47: -E2 + 100nM Palbo #2 | K47: =E47/B6 -> 1.7222222
A48: +E2 +250nM Palbo #3 | B48: ='Rep1'!B53 -> 2259 | D48: -E2 + 100nM Palbo #3 | E48: ='Rep1'!J53 -> 72 | G48: +E2 +250nM Palbo #3 | H48: =B48/B7 -> 52.534884 | J48: -E2 + 100nM Palbo #3 | K48: =E48/B7 -> 1.6744186
