Workbook

Sheet Sheet1
A1: T=0 for Month 1 (5/16/23)
A2: (same for all treatments)
A3: Sample | B3: Counter Read | C3: Cells/mL | D3: mL of cells | E3: Total cell number | F3: Average total cell # | G3: Stdev
A4: T=0 #1 | B4: 74 | C4: =B4*400 -> 29600 | D4: 2.5 | E4: =C4*D4 -> 74000 | F4: =AVERAGE(E4:E6) -> 69333.333 | G4: =_xlfn.STDEV.S(E4:E6) -> 5686.2407
A5: T=0 #2 | B5: 63 | C5: =B5*400 -> 25200 | D5: 2.5 | E5: =C5*D5 -> 63000
A6: T=0 #3 | B6: 71 | C6: =B6*400 -> 28400 | D6: 2.5 | E6: =C6*D6 -> 71000
A8: Month 1 (6/12/23)
A9: 750nM Palbo | I9: Constant ICI 750nM
A10: Sample | B10: Counter Read | C10: Cells/mL | D10: mL of cells | E10: Total cell number | F10: Average total cell # | G10: Stdev | I10: Sample | J10: Counter Read | K10: Cells/mL | L10: mL of cells | M10: Total cell number | N10: Average total cell # | O10: Stdev
A11: 1 month Palbo #1 | B11: 35 | C11: =B11*400 -> 14000 | D11: 2.5 | E11: =C11*D11 -> 35000 | F11: =AVERAGE(E11:E13) -> 31000 | G11: =_xlfn.STDEV.S(E11:E13) -> 4000 | I11: 1 month ICI #1 | J11: 878 | K11: =J11*400 -> 351200 | L11: 2.5 | M11: =K11*L11 -> 878000 | N11: =AVERAGE(M11:M13) -> 896333.33 | O11: =_xlfn.STDEV.S(K11:K13) -> 7203.7028
A12: 1 month Palbo #2 | B12: 27 | C12: =B12*400 -> 10800 | D12: 2.5 | E12: =C12*D12 -> 27000 | I12: 1 month ICI #2 | J12: 897 | K12: =J12*400 -> 358800 | L12: 2.5 | M12: =K12*L12 -> 897000
A13: 1 month Palbo #3 | B13: 31 | C13: =B13*400 -> 12400 | D13: 2.5 | E13: =C13*D13 -> 31000 | I13: 1 month ICI #3 | J13: 914 | K13: =J13*400 -> 365600 | L13: 2.5 | M13: =K13*L13 -> 914000
A14: 250nM AZD1775 | I14: AZD1775+ICI
A15: Sample | B15: Counter Read | C15: Cells/mL | D15: mL of cells | E15: Total cell number | F15: Average total cell # | G15: Stdev | I15: Sample | J15: Counter Read | K15: Cells/mL | L15: mL of cells | M15: Total cell number | N15: Average total cell # | O15: Stdev
A16: 1 month AZD #1 | B16: 4359 | C16: =B16*400 -> 1743600 | D16: 2.5 | E16: =C16*D16 -> 4359000 | F16: =AVERAGE(E16:E18) -> 4661666.7 | G16: =_xlfn.STDEV.S(E16:E18) -> 264577.65 | I16: 1 month AZD+ICI #1 | J16: 28 | K16: =J16*400 -> 11200 | L16: 2.5 | M16: =K16*L16 -> 28000 | N16: =AVERAGE(M16:M18) -> 35333.333 | O16: =_xlfn.STDEV.S(K16:K18) -> 3780.6525
A17: 1 month AZD #2 | B17: 4849 | C17: =B17*400 -> 1939600 | D17: 2.5 | E17: =C17*D17 -> 4849000 | I17: 1 month AZD+ICI #2 | J17: 46 | K17: =J17*400 -> 18400 | L17: 2.5 | M17: =K17*L17 -> 46000
A18: 1 month AZD #3 | B18: 4777 | C18: =B18*400 -> 1910800 | D18: 2.5 | E18: =C18*D18 -> 4777000 | I18: 1 month AZD+ICI #3 | J18: 32 | K18: =J18*400 -> 12800 | L18: 2.5 | M18: =K18*L18 -> 32000
A19: End of month 1 notes: Palbo plates very sparce. AZD+ICI plates also very sparce but not as sparce as Palbo. ICI plates ~85% confluent, cells flattened and spread out in large colonies. AZD plates VERY confluent, cells growing ontop of eachother, very clumpy, lots of floaters, possibly due to overgrowth (when lysing, did not collect floaters for these).
A22: New T=0 for Month 2 (6/13/23) Plated 70k
A23: Constant Palbo 750nM | I23: Constant ICI 750nM
A24: Sample | B24: Counter Read | C24: Cells/mL | D24: mL of cells | E24: Total cell number | F24: Average total cell # | G24: Stdev | I24: Sample | J24: Counter Read | K24: Cells/mL | L24: mL of cells | M24: Total cell number | N24: Average total cell # | O24: Stdev
A25: New T=0 for Month 2 | B25: 35 | C25: =B25*400 -> 14000 | D25: 2.5 | E25: =C25*D25 -> 35000 | F25: =AVERAGE(E25:E27) -> 31000 | G25: =_xlfn.STDEV.S(E25:E27) -> 4000 | I25: New T=0 for Month 2 | J25: 58 | K25: =J25*400 -> 23200 | L25: 2.5 | M25: =K25*L25 -> 58000 | N25: =AVERAGE(M25:M27) -> 59333.333 | O25: =_xlfn.STDEV.S(K25:K27) -> 2052.6406
A26: New T=0 for Month 2 | B26: 27 | C26: =B26*400 -> 10800 | D26: 2.5 | E26: =C26*D26 -> 27000 | I26: New T=0 for Month 2 | J26: 55 | K26: =J26*400 -> 22000 | L26: 2.5 | M26: =K26*L26 -> 55000
A27: New T=0 for Month 2 | B27: 31 | C27: =B27*400 -> 12400 | D27: 2.5 | E27: =C27*D27 -> 31000 | I27: New T=0 for Month 2 | J27: 65 | K27: =J27*400 -> 26000 | L27: 2.5 | M27: =K27*L27 -> 65000
A28: 250nM AZD1775 | I28: AZD1775+ICI
A29: Sample | B29: Counter Read | C29: Cells/mL | D29: mL of cells | E29: Total cell number | F29: Average total cell # | G29: Stdev | I29: Sample | J29: Counter Read | K29: Cells/mL | L29: mL of cells | M29: Total cell number | N29: Average total cell # | O29: Stdev
A30: New T=0 for Month 2 | B30: 48 | C30: =B30*400 -> 19200 | D30: 2.5 | E30: =C30*D30 -> 48000 | F30: =AVERAGE(E30:E32) -> 55000 | G30: =_xlfn.STDEV.S(E30:E32) -> 6557.4385 | I30: New T=0 for Month 2 | J30: 28 | K30: =J30*400 -> 11200 | L30: 2.5 | M30: =K30*L30 -> 28000 | N30: =AVERAGE(M30:M32) -> 35333.333 | O30: =_xlfn.STDEV.S(K30:K32) -> 3780.6525
A31: New T=0 for Month 2 | B31: 61 | C31: =B31*400 -> 24400 | D31: 2.5 | E31: =C31*D31 -> 61000 | I31: New T=0 for Month 2 | J31: 46 | K31: =J31*400 -> 18400 | L31: 2.5 | M31: =K31*L31 -> 46000
A32: New T=0 for Month 2 | B32: 56 | C32: =B32*400 -> 22400 | D32: 2.5 | E32: =C32*D32 -> 56000 | I32: New T=0 for Month 2 | J32: 32 | K32: =J32*400 -> 12800 | L32: 2.5 | M32: =K32*L32 -> 32000
A33: Alternating: 750nM Palbo/400nM ICI+200nM Palbo: 1 month Palbo--> | I33: Alternating: 750nM Palbo/750nM ICI+250nM AZD1775: 1 month Palbo -->
A34: Sample | B34: Counter Read | C34: Cells/mL | D34: mL of cells | E34: Total cell number | F34: Average total cell # | G34: Stdev | I34: Sample | J34: Counter Read | K34: Cells/mL | L34: mL of cells | M34: Total cell number | N34: Average total cell # | O34: Stdev
A35: New T=0 for Month 2 | B35: 36 | C35: =B35*400 -> 14400 | D35: 2.5 | E35: =C35*D35 -> 36000 | F35: =AVERAGE(E35:E37) -> 30000 | G35: =_xlfn.STDEV.S(E35:E37) -> 5196.1524 | I35: New T=0 for Month 2 | J35: 37 | K35: =J35*400 -> 14800 | L35: 2.5 | M35: =K35*L35 -> 37000 | N35: =AVERAGE(M35:M37) -> 33666.667 | O35: =_xlfn.STDEV.S(K35:K37) -> 1404.7538
A36: New T=0 for Month 2 | B36: 27 | C36: =B36*400 -> 10800 | D36: 2.5 | E36: =C36*D36 -> 27000 | I36: New T=0 for Month 2 | J36: 30 | K36: =J36*400 -> 12000 | L36: 2.5 | M36: =K36*L36 -> 30000
A37: New T=0 for Month 2 | B37: 27 | C37: =B37*400 -> 10800 | D37: 2.5 | E37: =C37*D37 -> 27000 | I37: New T=0 for Month 2 | J37: 34 | K37: =J37*400 -> 13600 | L37: 2.5 | M37: =K37*L37 -> 34000
A38: Re-plated each condition into 5-6 plates with drugs in media with 70k cells. Palbo cells and AZD+ICI cells didn't all re-attach, new plates very very sparce.
A40: Month 2 (7/10/23)
A41: 750nM Palbo | I41: Constant ICI 750nM
A42: Sample | B42: Counter Read | C42: Cells/mL | D42: mL of cells | E42: Total cell number | F42: Average total cell # | G42: Stdev | I42: Sample | J42: Counter Read | K42: Cells/mL | L42: mL of cells | M42: Total cell number | N42: Average total cell # | O42: Stdev
A43: 2 month Palbo | B43: 18 | C43: =B43*400 -> 7200 | D43: 2.5 | E43: =C43*D43 -> 18000 | F43: =AVERAGE(E43:E45) -> 20333.333 | G43: =_xlfn.STDEV.S(E43:E45) -> 2516.6115 | I43: 2 month ICI | J43: 1340 | K43: =J43*400 -> 536000 | L43: 2.5 | M43: =K43*L43 -> 1340000 | N43: =AVERAGE(M43:M45) -> 1397000 | O43: =_xlfn.STDEV.S(K43:K45) -> 28534.891
A44: 2 month Palbo | B44: 23 | C44: =B44*400 -> 9200 | D44: 2.5 | E44: =C44*D44 -> 23000 | I44: 2 month ICI | J44: 1374 | K44: =J44*400 -> 549600 | L44: 2.5 | M44: =K44*L44 -> 1374000
...

Sheet Sheet2
A1: Day 0
A2: Sample
A3: T=0 #1 | B3: =Sheet1!E4 -> 74000
A4: T=0 #2 | B4: =Sheet1!E5 -> 63000
A5: T=0 #3 | B5: =Sheet1!E6 -> 71000
B6: =AVERAGE(B3:B5) -> 69333.333
A8: Month 1 | D8: Month 1
A9: Palbo 750nM | B9: Constant ICI 750nM | D9: Palbo 750nM | E9: ICI 750nM
A10: =Sheet1!E11 -> 35000 | B10: =Sheet1!M11 -> 878000 | D10: =A10/B6 -> 0.50480769 | E10: =B10/B6 -> 12.663462
A11: =Sheet1!E12 -> 27000 | B11: =Sheet1!M12 -> 897000 | D11: =A11/B6 -> 0.38942308 | E11: =B11/B6 -> 12.9375
A12: =Sheet1!E13 -> 31000 | B12: =Sheet1!M13 -> 914000 | D12: =A12/B6 -> 0.44711538 | E12: =B12/B6 -> 13.182692
D13: =AVERAGE(D10:D12) -> 0.44711538 | E13: =AVERAGE(E10:E12) -> 12.927885
A14: 250nM AZD1775 | B14: AZD1775+ICI | D14: 250nM AZD1775 | E14: AZD1775+ICI
A15: =Sheet1!E16 -> 4359000 | B15: =Sheet1!M16 -> 28000 | D15: =A15/B6 -> 62.870192 | E15: =B15/B6 -> 0.40384615
A16: =Sheet1!E17 -> 4849000 | B16: =Sheet1!M17 -> 46000 | D16: =A16/B6 -> 69.9375 | E16: =B16/B6 -> 0.66346154
A17: =Sheet1!E18 -> 4777000 | B17: =Sheet1!M18 -> 32000 | D17: =A17/B6 -> 68.899038 | E17: =B17/B6 -> 0.46153846
D18: =AVERAGE(D15:D17) -> 67.235577 | E18: =AVERAGE(E15:E17) -> 0.50961538
A19: Alternating: 750nM Palbo/400nM ICI+200nM Palbo | B19: Alternating: 750nM Palbo/750nM ICI+250nM AZD1775 | D19: Alternating: 750nM Palbo/400nM ICI+200nM Palbo | E19: Alternating: 750nM Palbo/750nM ICI+250nM AZD1775
A20: =A10 -> 35000 | B20: =A10 -> 35000 | D20: =A20/B6 -> 0.50480769 | E20: =B20/B6 -> 0.50480769
A21: =A11 -> 27000 | B21: =A11 -> 27000 | D21: =A21/B6 -> 0.38942308 | E21: =B21/B6 -> 0.38942308
A22: =A12 -> 31000 | B22: =A12 -> 31000 | D22: =A22/B6 -> 0.44711538 | E22: =B22/B6 -> 0.44711538
A26: New T=0 for Month 2
A27: Palbo 750nM | B27: ICI 750nM
A28: =Sheet1!E25 -> 35000 | B28: =Sheet1!M25 -> 58000
A29: =Sheet1!E26 -> 27000 | B29: =Sheet1!M26 -> 55000
A30: =Sheet1!E27 -> 31000 | B30: =Sheet1!M27 -> 65000
A31: =AVERAGE(A28:A30) -> 31000 | B31: =AVERAGE(B28:B30) -> 59333.333
A33: 250nM AZD1775 | B33: AZD1775+ICI
A34: =Sheet1!E30 -> 48000 | B34: =Sheet1!M30 -> 28000
A35: =Sheet1!E31 -> 61000 | B35: =Sheet1!M31 -> 46000
A36: =Sheet1!E32 -> 56000 | B36: =Sheet1!M32 -> 32000
A37: =AVERAGE(A34:A36) -> 55000 | B37: =AVERAGE(B34:B36) -> 35333.333
A39: Alternating: 750nM Palbo/400nM ICI+200nM Palbo | B39: Alternating: 750nM Palbo/750nM ICI+250nM AZD1775
A40: =Sheet1!E35 -> 36000 | B40: =Sheet1!M35 -> 37000
A41: =Sheet1!E36 -> 27000 | B41: =Sheet1!M36 -> 30000
A42: =Sheet1!E37 -> 27000 | B42: =Sheet1!M37 -> 34000
A43: =AVERAGE(A40:A42) -> 30000 | B43: =AVERAGE(B40:B42) -> 33666.667
A46: Month 2 | D46: Month 2
A47: Constant Palbo 750nM | B47: Constant ICI 750nM | D47: Palbo 750nM | E47: ICI 750nM
A48: =Sheet1!E43 -> 18000 | B48: =Sheet1!M43 -> 1340000 | D48: =A48/A31 -> 0.58064516 | E48: =B48/B31 -> 22.58427
...
